Workbook

Sheet Calc
A2: CONTAMINAZIONE DA Sr-90 | S2: Anastasi Michele
A6: STAGE 1 | B6: MISURE | L6: IPOTESI
B7: Escrezione urinaria | L7: Forma chimica: sconosciuta, ipotizzo eventualmente particolato in fuga da impianto dopo incidente
B8: Giorni dopo | C8: Misura [Bq/l] | D8: Incertezza [+/-] | E8: Incertezza [Bq/l] | F8: Norm [l/d] | G8: Misura [Bq/d] | H8: Incertezza [Bq/d] | L8: Solo una narice contaminata, quindi dovuto ad inaccortezza (strofinamento), da cui:
B9: 3 | C9: 637.5 | D9: 0.14 | E9: =C9*D9 -> 89.25 | F9: 1.6 | G9: =C9*F9 -> 1020 | H9: =G9*D9 -> 142.8 | L9: Possibile ipotesi iniziale di sola ingestione, sostenuta inoltre dal fatto che ha piovuto e dunque lo Sr-90 (fall-out) si è depositato sui vegetali (famiglia, in area rurale, dedita ad agricoltura)
B10: 6 | C10: 356.2 | D10: 0.14 | E10: =C10*D10 -> 49.868 | F10: 1.6 | G10: =C10*F10 -> 569.92 | H10: =G10*D10 -> 79.7888 | L10: Ipotizzo no intake tra gli esami (evacuazione)
B12: Escrezione fecale | L12: NOTA sulla legenda
B13: Giorni dopo | C13: Misura [Bq/g] | D13: Incertezza [+/-] | E13: Incertezza [Bq/g] | F13: Norm [g/d] | G13: Misura [Bq/d] | H13: Incertezza [Bq/d] | L13: Dati evidenziati: | N13: celle collegate ad altri fogli
B14: 6 | C14: 3.7 | D14: 0.16 | E14: =C14*D14 -> 0.592 | F14: 150 | G14: =C14*F14 -> 555 | H14: =G14*D14 -> 88.8
B15: 13 | C15: 0.6 | D15: 0.16 | E15: =C15*D15 -> 0.096 | F15: 150 | G15: =C15*F15 -> 90 | H15: =G15*D15 -> 14.4
A19: 1.2 | B19: Valutazione Mc
B20: Monitoraggio SPECIALE
B21: Ipotizzo ingestione, supportato da campione nasale (si veda ipotesi iniziali)
B23: m(3) [Bq/d*Bq] | C23: ='OIR - Ingestion m(t)'!C11 -> 0.012 | E23: Mc [Bq/d] | F23: =C23*C25/C24 -> 50
B24: e(50) [Sv/Bq] | C24: ='OIR - Dose coefficients e(50)'!C7 -> 2.4e-08 | F24: =IF(F23<F25,"<",">") -> < | H24: =IF(F23<F25,"Occorre valutazione ulteriore","Non occorre valutazione") -> Occorre valutazione ulteriore
B25: E(rif) [Sv] | C25: =0.1*0.001 -> 0.0001 | E25: M(u d=3) Bq/d] | F25: =G9 -> 1020
H26: dato usato: misure urine +3 giorni
A30: STAGE 2 | B30: Valutazione intake ed E(50) al fine di stima OdG
B31: NOTA: | C31: Ipotizzo ingestione, supportato da campione nasale(vedi ipotesi iniziali)
B33: m(3) [Bq/d*Bq] | C33: ='OIR - Ingestion m(t)'!C11 -> 0.012 | E33: Intake [Bq] | F33: =G9/C33 -> 85000
B34: e(50) [Sv/Bq] | C34: ='OIR - Dose coefficients e(50)'!C7 -> 2.4e-08 | E34: E(50) [mSv] | F34: =F33*C34*1000 -> 2.04 | H34: dato usato per stima OdG: misure urine +3 giorni
A36: 2.1 | B36: Scattering factor
B37: SF(A) | C37: =EXP(H9/G9) -> 1.1502738 | E37: SF | F37: =EXP(SQRT(LN(C37)^2+LN(C38)^2)) -> 1.1845508
B38: SF(B) | C38: 1.1
A40: 2.2 | B40: Ipotizzo no intake tra gli esami, in virtù della evacuazione e del successivo stretto controllo medico
B41: No intake precedenti (scenario incidentale e Sr-90 non è un NORM...), dunque:
B42: P [Bq] | C42: 0
A44: 2.3 | B44: M(u d=3) [Bq/d] | C44: =G9 -> 1020
C45: =IF(C44>C46,">","<") -> > | E45: =IF(C44>C46,"Presenza di un nuovo intake (essendo evento incidentale)","Nessun nuovo intake") -> Presenza di un nuovo intake (essendo evento incidentale)
B46: P*SF*SF | C46: =F37*F37*C42 -> 0
A49: STAGE 3 | B49: Monitoraggio speciale: scenario incidentale
A53: STAGE 4 | B53: Ipotizzo pura ingestione
A55: STAGE 6.1 | B55: Sintesi misure disponibili + SF associati
B57: =B8 -> Giorni dopo | C57: Metodica | D57: =G8 -> Misura [Bq/d] | E57: =H8 -> Incertezza [Bq/d] | F57: SF(A) | G57: SF(B) | H57: SF
B58: =B9 -> 3 | C58: Urine | D58: =G9 -> 1020 | E58: =H9 -> 142.8 | F58: =EXP(E58/D58) -> 1.1502738 | G58: 1.1 | H58: =EXP(SQRT(LN(F58)^2+LN(G58)^2)) -> 1.1845508
B59: =B10 -> 6 | C59: Urine | D59: =G10 -> 569.92 | E59: =H10 -> 79.7888 | F59: =EXP(E59/D59) -> 1.1502738 | G59: 1.1 | H59: =EXP(SQRT(LN(F59)^2+LN(G59)^2)) -> 1.1845508
B60: =B14 -> 6 | C60: Feci | D60: =G14 -> 555 | E60: =H14 -> 88.8 | F60: =EXP(E60/D60) -> 1.1735109 | G60: 3 | H60: =EXP(SQRT(LN(F60)^2+LN(G60)^2)) -> 3.0349721
B61: =B15 -> 13 | C61: Feci | D61: =G15 -> 90 | E61: =H15 -> 14.4 | F61: =EXP(E61/D61) -> 1.1735109 | G61: 3 | H61: =EXP(SQRT(LN(F61)^2+LN(G61)^2)) -> 3.0349721
A64: 6.2 | B64: =B41 -> No intake precedenti (scenario incidentale e Sr-90 non è un NORM...), dunque:
A66: 6.3 | B66: Parametri a priori
...

Sheet OIR - Ingestion m(t)
B2: Radionuclide | C2: Sr-90 | J2: Radionuclide | K2: Sr-90
B3: Route of Intake | C3: Ingestion | J3: Route of Intake | K3: Ingestion
B4: Material | C4: All other chemical forms, fA=0,25 | J4: Material | K4: Strontium titanate, fA=1E-2
B5: AMTD/AMAD, µm | C5: - | J5: AMTD/AMAD, µm | K5: -
B7: Content in an Organ or Excreta Sample per Intake (Reference Bioassay Functions m(t)), Bq per Bq | J7: Content in an Organ or Excreta Sample per Intake (Reference Bioassay Functions m(t)), Bq per Bq
B8: Time, days | C8: Urine (24-hour sample) | D8: Faeces (24-hour sample) | J8: Time, days | K8: Urine (24-hour sample) | L8: Faeces (24-hour sample)
B9: 1 | C9: 0.047 | D9: 0.18 | J9: 1 | K9: 0.0018 | L9: 0.21
B10: 2 | C10: 0.019 | D10: 0.36 | J10: 2 | K10: 0.00076 | L10: 0.47
B11: 3 | C11: 0.012 | D11: 0.17 | J11: 3 | K11: 0.00049 | L11: 0.22
B12: 4 | C12: 0.0089 | D12: 0.052 | J12: 4 | K12: 0.00036 | L12: 0.066
B13: 5 | C13: 0.007 | D13: 0.014 | J13: 5 | K13: 0.00028 | L13: 0.016
B14: 6 | C14: 0.0057 | D14: 0.0048 | J14: 6 | K14: 0.00023 | L14: 0.0034
B15: 7 | C15: 0.0047 | D15: 0.0024 | J15: 7 | K15: 0.00019 | L15: 0.00072
B16: 8 | C16: 0.004 | D16: 0.0017 | J16: 8 | K16: 0.00016 | L16: 0.00018
B17: 9 | C17: 0.0035 | D17: 0.0013 | J17: 9 | K17: 0.00014 | L17: 7.4e-05
B18: 10 | C18: 0.0031 | D18: 0.0011 | J18: 10 | K18: 0.00012 | L18: 5e-05
B19: 11 | C19: 0.0028 | D19: 0.001 | J19: 11 | K19: 0.00011 | L19: 4.1e-05
B20: 12 | C20: 0.0025 | D20: 0.00089 | J20: 12 | K20: 0.0001 | L20: 3.6e-05
... B252: 18250 | C252: 7.3e-08 | D252: 2.2e-08 | J252: 18250 | K252: 2.9e-09 | L252: 8.8e-10

Sheet OIR - Dose coefficients e(50)
B2: Radionuclide | C2: Sr-90
B3: Units | C3: Sv per Bq
B5: Material | C5: Dose Coefficient e(50)
B6: Ingestion, Strontium titanate, fA=1E-2 | C6: 1.1e-09
B7: Ingestion, All other chemical forms, fA=0,25 | C7: 2.4e-08
B8: Inhalation, Aerosols Type F, Strontium chloride, sulphate and carbonate, fA=0,25, 5 µm | C8: 3.2e-08
B9: Inhalation, Aerosols Type M, Fuel fragments, all unspecified forms, fA=5E-2, 5 µm | C9: 1.8e-08
B10: Inhalation, Aerosols Type S, FAP, PSL, fA=2,5E-3, 5 µm | C10: 2e-07
B12: Inhalation, Aerosols Type F, Strontium chloride, sulphate and carbonate, fA=0,25, 1 µm | C12: 2.5e-08
B13: Inhalation, Aerosols Type M, Fuel fragments, all unspecified forms, fA=5E-2, 1 µm | C13: 3e-08
B14: Inhalation, Aerosols Type S, FAP, PSL, fA=2,5E-3, 1 µm | C14: 3.8e-07
